Workbook

Sheet 经纬度-产能
A1: 企业名称 | B1: 所在省份 | C1: Province | D1: 产能 (千吨/年) | E1: 产能 （吨/日） | F1: City | G1: 城市 | I1: 经度 | J1: 纬度
A2: 中安联合 | B2: 安徽省 | C2: Anhui | D2: 1800 | E2: =D2*1000/8500 -> 211.76471 | F2: Huainan | G2: 淮南市 | I2: 116.87979 | J2: 32.694851
A3: 安徽昊源 | B3: 安徽省 | C3: Anhui | D3: 1400 | E3: =D3*1000/8500 -> 164.70588 | F3: Fuyang | G3: 阜阳市 | I3: 115.86363 | J3: 32.92695
A4: 临涣焦化煤炭 | B4: 安徽省 | C4: Anhui | D4: 900 | E4: =D4*1000/8500 -> 105.88235 | F4: Huaibei | G4: 淮北市 | I4: 116.58695 | J4: 33.609699
A5: 晋煤中能 | B5: 安徽省 | C5: Anhui | D5: 600 | E5: =D5*1000/8500 -> 70.588235 | F5: Fuyang | G5: 阜阳市 | I5: 115.28816 | J5: 33.060924
A6: 安徽华谊 | B6: 安徽省 | C6: Anhui | D6: 500 | E6: =D6*1000/8500 -> 58.823529 | F6: Wuhu | G6: 芜湖市 | I6: 118.33088 | J6: 31.369512
A7: 安徽曙光 | B7: 安徽省 | C7: Anhui | D7: 160 | E7: =D7*1000/8500 -> 18.823529 | F7: Anqing | G7: 安庆市 | I7: 116.9975 | J7: 30.539126
A8: 安徽泉盛 | B8: 安徽省 | C8: Anhui | D8: 150 | E8: =D8*1000/8500 -> 17.647059 | F8: Chuzhou | G8: 滁州市 | I8: 117.27879 | J8: 32.579821
A9: 安徽红四方 | B9: 安徽省 | C9: Anhui | D9: 100 | E9: =D9*1000/8500 -> 11.764706 | F9: Hefei | G9: 合肥市 | I9: 117.51513 | J9: 31.776991
A10: 川维 | B10: 重庆市 | C10: Chongqing | D10: 870 | E10: =D10*1000/8500 -> 102.35294 | F10: Chongqing | G10: 重庆市 | I10: 107.01438 | J10: 29.795963
A11: 卡贝乐化工 | B11: 重庆市 | C11: Chongqing | D11: 850 | E11: =D11*1000/8500 -> 100 | F11: Chongqing | G11: 重庆市 | I11: 107.04969 | J11: 29.819159
A12: 重庆建滔 | B12: 重庆市 | C12: Chongqing | D12: 450 | E12: =D12*1000/8500 -> 52.941176 | F12: Chongqing | G12: 重庆市 | I12: 106.98833 | J12: 29.81429
A13: 重庆万盛 | B13: 重庆市 | C13: Chongqing | D13: 300 | E13: =D13*1000/8500 -> 35.294118 | F13: Chongqing | G13: 重庆市 | I13: 106.79158 | J13: 28.84734
... A117: 蒲城清洁能源 | B117: 陕西省 | C117: Shaanxi | D117: 1800 | E117: =D117*1000/8500 -> 211.76471 | F117: Weinan | G117: 渭南市 | I117: 109.72208 | J117: 34.908427
A118: 延长石油延安能化 | B118: 陕西省 | C118: Shaanxi | D118: 1800 | E118: =D118*1000/8500 -> 211.76471
A119: 国能榆林能源 | B119: 陕西省 | C119: Shaanxi | D119: 1800 | E119: =D119*1000/8500 -> 211.76471 | F119: Yulin | G119: 榆林市 | I119: 109.74925 | J119: 38.235436
A120: 中煤陕西榆林 | B120: 陕西省 | C120: Shaanxi | D120: 1800 | E120: =D120*1000/8500 -> 211.76471 | F120: Yulin | G120: 榆林市 | I120: 109.53931 | J120: 38.152078
A121: 兖矿榆林 | B121: 陕西省 | C121: Shaanxi | D121: 1200 | E121: =D121*1000/8500 -> 141.17647 | F121: Yulin | G121: 榆林市 | I121: 109.48826 | J121: 38.22228
A122: 凯越煤化 | B122: 陕西省 | C122: Shaanxi | D122: 700 | E122: =D122*1000/8500 -> 82.352941 | F122: Yulin | G122: 榆林市 | I122: 109.60859 | J122: 38.147445
A123: 神木化工 | B123: 陕西省 | C123: Shaanxi | D123: 600 | E123: =D123*1000/8500 -> 70.588235 | F123: Yulin | G123: 榆林市 | I123: 110.17817 | J123: 38.745865
A124: 长青能源 | B124: 陕西省 | C124: Shaanxi | D124: 600 | E124: =D124*1000/8500 -> 70.588235 | F124: Baoji | G124: 宝鸡市 | I124: 107.27474 | J124: 34.460065
A125: 陕西渭化 | B125: 陕西省 | C125: Shaanxi | D125: 600 | E125: =D125*1000/8500 -> 70.588235 | F125: Weinan | G125: 渭南市 | I125: 109.72222 | J125: 34.470492
A126: 润中清洁能源 | B126: 陕西省 | C126: Shaanxi | D126: 600 | E126: =D126*1000/8500 -> 70.588235 | F126: Xianyang | G126: 咸阳市 | I126: 107.76687 | J126: 35.214496
A127: 陕西兴化 | B127: 陕西省 | C127: Shaanxi | D127: 300 | E127: =D127*1000/8500 -> 35.294118 | F127: Xianyang | G127: 咸阳市 | I127: 108.51497 | J127: 34.284772
A128: 黄陵煤化工 | B128: 陕西省 | C128: Shaanxi | D128: 300 | E128: =D128*1000/8500 -> 35.294118 | F128: Yanan | G128: 延安市 | I128: 109.06672 | J128: 35.621322
A129: 延长榆林煤化 | B129: 陕西省 | C129: Shaanxi | D129: 300 | E129: =D129*1000/8500 -> 35.294118 | F129: Yulin | G129: 榆林市 | I129: 109.59583 | J129: 38.152368
A130: 陕西精益 | B130: 陕西省 | C130: Shaanxi | D130: 260 | E130: =D130*1000/8500 -> 30.588235 | F130: Yulin | G130: 榆林市 | I130: 110.20932 | J130: 38.726963
... A183: 泸天化 | B183: 四川省 | C183: Sichuan | D183: 450 | E183: =D183*1000/8500 -> 52.941176 | F183: Luzhou | G183: 泸州市 | I183: 105.38009 | J183: 28.77434
A184: 达州钢铁 | B184: 四川省 | C184: Sichuan | D184: 400 | E184: =D184*1000/8500 -> 47.058824 | I184: 121.96621 | J184: 30.311938
A185: 万利 | B185: 四川省 | C185: Sichuan | D185: 150 | E185: =D185*1000/8500 -> 17.647059 | F185: Mianyang | G185: 绵阳市 | I185: 104.80796 | J185: 31.81094
A186: 天津渤化永利 | B186: 天津市 | C186: Tianjin | D186: 500 | E186: =D186*1000/8500 -> 58.823529 | F186: Tianjin | G186: 天津市 | I186: 117.72578 | J186: 38.937056
A187: 神华煤制油新疆 | B187: 新疆维吾尔自治区 | C187: Xinjiang | D187: 1800 | E187: =D187*1000/8500 -> 211.76471 | F187: Urumqi | G187: 乌鲁木齐市 | I187: 116.398 | J187: 39.95098
A188: 广汇新能源 | B188: 新疆维吾尔自治区 | C188: Xinjiang | D188: 1200 | E188: =D188*1000/8500 -> 141.17647 | F188: Hami | G188: 哈密市 | I188: 87.59586 | J188: 43.892439
A189: 新疆天智辰业 | B189: 新疆维吾尔自治区 | C189: Xinjiang | D189: 600 | E189: =D189*1000/8500 -> 70.588235 | F189: Shihezi | G189: 石河子市 | I189: 86.043845 | J189: 44.370539
A190: 新疆新业物流 | B190: 新疆维吾尔自治区 | C190: Xinjiang | D190: 500 | E190: =D190*1000/8500 -> 58.823529 | F190: Wujiaqu | G190: 五家渠市 | I190: 87.689891 | J190: 44.360219
A191: 巴州东辰 | B191: 新疆维吾尔自治区 | C191: Xinjiang | D191: 480 | E191: =D191*1000/8500 -> 56.470588 | F191: Qunbak | G191: 轮台县群巴克镇 | I191: 84.103065 | J191: 41.851805
A192: 兖矿新疆 | B192: 新疆维吾尔自治区 | C192: Xinjiang | D192: 300 | E192: =D192*1000/8500 -> 35.294118 | F192: Urumqi | G192: 乌鲁木齐市 | I192: 87.78353 | J192: 44.155046
A193: 新疆国泰新华矿业 | B193: 新疆维吾尔自治区 | C193: Xinjiang | D193: 200 | E193: =D193*1000/8500 -> 23.529412 | F193: Jimsar | G193: 吉木萨尔县 | I193: 89.085134 | J193: 44.716245
A194: 库车新成 | B194: 新疆维吾尔自治区 | C194: Xinjiang | D194: 200 | E194: =D194*1000/8500 -> 23.529412 | F194: Aksu | G194: 阿克苏地区（白水城） | I194: 83.096763 | J194: 41.741459
A195: 拜城众泰 | B195: 新疆维吾尔自治区 | C195: Xinjiang | D195: 200 | E195: =D195*1000/8500 -> 23.529412 | F195: Aksu | G195: 阿克苏地区拜城县拜城镇 | I195: 81.79093 | J195: 41.83981
...

Sheet Province
A1: Province | B1: City | C1: Total annual capacity (kton/yr) | D1: Hourly capacity (ton/hr) | E1: Company | F1: Capacity | G1: Lons | H1: Lats | I1: 工艺
A2: Ningxia | B2: Yinchuan | C2: =SUM(F3:F7) -> 11740 | D2: =C2*1000/8760 -> 1340.1826
E3: 宝丰能源 | F3: 6720 | G3: 106.557 | H3: 38.2335 | I3: 煤/焦炉气制甲醇
E4: 国家能源宁夏煤业 | F4: 3520 | G4: 106.63182 | H4: 38.192029 | I4: 煤制甲醇
E5: 中石化长城能源 | F5: 600 | G5: 106.57628 | H5: 38.15931 | I5: 煤制甲醇
E6: 宁夏鲲鹏 | F6: 600 | G6: 106.70092 | H6: 38.091787 | I6: 煤制甲醇
E7: 和宁化学 | F7: 300 | G7: 106.5947 | H7: 38.201156 | I7: 煤制甲醇
A8: Ningxia | B8: Wuzhong | C8: =F9 -> 150 | D8: =C8*1000/8760 -> 17.123288
E9: 宁夏庆华 | F9: 150 | G9: 106.57897 | H9: 37.411445 | I9: 焦炉煤气制甲醇
A10: Inner Mongolia | B10: Alxa League | C10: =F11+F12 -> 700 | D10: =C10*1000/8760 -> 79.908676
E11: 沪蒙能源 | F11: 400 | G11: 106.52777 | H11: 39.535131 | I11: 焦炉煤气制甲醇
E12: 内蒙古庆华 | F12: 300 | G12: 106.72311 | H12: 39.420228 | I12: 焦炉煤气制甲醇
A13: Inner Mongolia | B13: Bayan Nu | C13: 300 | D13: =C13*1000/8760 -> 34.246575
E14: 内蒙古黑猫 | F14: 300 | G14: 106.78479 | H14: 40.941142 | I14: 焦炉煤气制甲醇
A15: Inner Mongolia | B15: Baotou | C15: =SUM(F16:F18) -> 2100 | D15: =C15*1000/8760 -> 239.72603
E16: 神华包头 | F16: 1800 | G16: 109.86832 | H16: 40.599355 | I16: 煤制甲醇
E17: 包钢 | F17: 200 | G17: 109.78633 | H17: 40.665023 | I17: 焦炉煤气制甲醇
E18: 包头经纬 | F18: 100 | G18: 110.22035 | H18: 40.69634 | I18: 焦炉煤气制甲醇
A19: Inner Mongolia | B19: Chifeng | C19: =F20 -> 150 | D19: =C19*1000/8760 -> 17.123288
E20: 赤峰博元 | F20: 150 | G20: 116.77799 | H20: 43.068918 | I20: 天然气制甲醇
A21: Inner Mongolia | B21: Duolun | C21: =F22 -> 1680 | D21: =C21*1000/8760 -> 191.78082
E22: 大唐多伦 | F22: 1680 | G22: 116.5786 | H22: 42.210449 | I22: 煤制甲醇
A23: Inner Mongolia | B23: Ordos | C23: =SUM(F24:F40) -> 11470 | D23: =C23*1000/8760 -> 1309.3607
E24: 中天合创 | F24: 3600 | G24: 109.49015 | H24: 39.075071 | I24: 煤制甲醇
E25: 荣信化工 | F25: 1800 | G25: 110.05183 | H25: 40.278912 | I25: 煤制甲醇
E26: 新奥达旗 | F26: 1200 | G26: 110.08884 | H26: 40.327814 | I26: 煤制甲醇
E27: 中煤鄂尔多斯 | F27: 1000 | G27: 109.48368 | H27: 39.089699 | I27: 煤制甲醇
E28: 中煤远兴 | F28: 600 | G28: 108.97862 | H28: 38.085754 | I28: 煤制甲醇
E29: 内蒙古东华 | F29: 600 | G29: 110.8511 | H29: 39.7051 | I29: 煤制甲醇
E30: 鄂尔多斯国泰 | F30: 400 | G30: 116.12034 | H30: 39.570244 | I30: 煤制甲醇
E31: 苏里格天然气化工 | F31: 350 | G31: 108.97447 | H31: 39.270619 | I31: 天然气制甲醇
E32: 西北能源 | F32: 300 | G32: 109.97805 | H32: 39.827625 | I32: 煤制甲醇
E33: 内蒙古易高煤化 | F33: 300 | G33: 116.44916 | H33: 39.830312 | I33: 煤制甲醇
E34: 内蒙金诚泰 | F34: 300 | G34: 109.55644 | H34: 38.898094 | I34: 煤制甲醇
E35: 世林化工 | F35: 300 | G35: 109.24683 | H35: 38.633345 | I35: 煤制甲醇
... E40: 九鼎化工 | F40: 100 | G40: 110.87329 | H40: 39.716436 | I40: 煤制甲醇
A41: Inner Mongolia | B41: Hohhot | C41: =SUM(F42:F44) -> 3300 | D41: =C41*1000/8760 -> 376.71233
E42: 内蒙古久泰 | F42: 3000 | G42: 111.32261 | H42: 40.194607 | I42: 煤制甲醇
E43: 中石油新材料 | F43: 200 | G43: 111.75521 | H43: 40.74525 | I43: 天然气制甲醇
E44: 旭阳中燃 | F44: 100 | G44: 111.42864 | H44: 40.176515 | I44: 焦炉煤气制甲醇
...

Sheet i,j
C1: 1 | D1: 2 | E1: 3 | F1: 4 | G1: 5 | H1: 6 | I1: 7 | J1: 8 | K1: 9 | L1: 10 | M1: 11 | N1: 12
A2: 1 | B2: Ningxia | C2: Yinchuan | D2: Wuzhong
A3: 2 | B3: Inner Mongolia | C3: Alxa League | D3: Bayan Nu | E3: Baotou | F3: Chifeng | G3: Duolun | H3: Ordos | I3: Hohhot | J3: Wuhai | K3: Ulanqab | L3: Bayan
A4: 3 | B4: Shaanxi | C4: Baoji | D4: Weinan | E4: Xianyang | F4: Yanan | G4: Yulin
A5: 4 | B5: Anhui | C5: Anqing | D5: Chuzhou | E5: Fuyang | F5: Hefei | G5: Huaibei | H5: Huainan | I5: Wuhu
A6: 5 | B6: Xinjiang | C6: Aksu | D6: Hami | E6: Jimsar | F6: Korla | G6: Qunbak | H6: Qitai | I6: Shihezi | J6: Urumqi | K6: Wujiaqu
A7: 6 | B7: Guangxi | C7: Qinzhou
A8: 7 | B8: Shandong | C8: Dezhou | D8: Heze | E8: Jinan | F8: Jining | G8: Liaocheng | H8: Linfen | I8: Linyi | J8: Taian | K8: Weifang | L8: Yantai | M8: Zaozhuang | N8: Zibo
A9: 8 | B9: Qinghai | C9: Golmud Mountain | D9: Xining | E9: Golmud
A10: 9 | B10: Hainan | C10: Dongfang
A11: 10 | B11: Shanghai | C11: Shanghai
A12: 11 | B12: Shanxi | C12: Datong | D12: Hengshui | E12: Jincheng | F12: Linfen | G12: Lvliang | H12: Shuozhou | I12: Taiyuan | J12: Yuncheng | K12: Changzhi
A13: 12 | B13: Chongqing | C13: Chongqing
A14: 13 | B14: Heilongjiang | C14: Daqing | D14: Harbin | E14: Qitaihe | F14: Qiqihar | G14: Shuangyashan
A15: 14 | B15: Henan | C15: Anyang | D15: Hebi | E15: Pingdingshan | F15: Puyang | G15: Sanmenxia | H15: Xinxiang | I15: Zhumadian
A16: 15 | B16: Gansu | C16: Pingliang | D16: Lanzhou | E16: Yongjing
A17: 16 | B17: Jiangxi | C17: Jiujiang
A18: 17 | B18: Tianjin | C18: Tianjin
A19: 18 | B19: Jiangsu | C19: Lianyungang | D19: Nanjing | E19: Suzhou | F19: Xuzhou
A20: 19 | B20: Sichuan | C20: Dazhou | D20: Luzhou | E20: Mianyang
A21: 20 | B21: Yunnan | C21: Kaiyuan | D21: Kunming | E21: Qujing | F21: Zhaotong
A22: 21 | B22: Liaoning | C22: Dalian
A23: 22 | B23: Hubei | C23: Jingmen | D23: Yichang
A24: 23 | B24: Zhejiang | C24: Zhoushan | D24: Ningbo
A25: 24 | B25: Hebei | C25: Baoding | D25: Cangzhou | E25: Handan | F25: Hengshui | G25: Shijiazhuang | H25: Tangshan
A26: 25 | B26: Guizhou | C26: Bijie | D26: Fuquan | E26: Guiyang | F26: Liupanshui | G26: Zunyi
A27: 26 | B27: Jilin | C27: Tonghua

Sheet Yr_tonne
C1: 1 | D1: 2 | E1: 3 | F1: 4 | G1: 5 | H1: 6 | I1: 7 | J1: 8 | K1: 9 | L1: 10 | M1: 11 | N1: 12
A2: 1 | B2: Ningxia | C2: =Yr!C2*1000 -> 11740000 | D2: =Yr!D2*1000 -> 150000 | E2: =Yr!E2*1000 -> 0 | F2: =Yr!F2*1000 -> 0 | G2: =Yr!G2*1000 -> 0 | H2: =Yr!H2*1000 -> 0 | I2: =Yr!I2*1000 -> 0 | J2: =Yr!J2*1000 -> 0 | ... N2: =Yr!N2*1000 -> 0
A3: 2 | B3: Inner Mongolia | C3: =Yr!C3*1000 -> 700000 | D3: =Yr!D3*1000 -> 300000 | E3: =Yr!E3*1000 -> 2100000 | F3: =Yr!F3*1000 -> 150000 | G3: =Yr!G3*1000 -> 1680000 | H3: =Yr!H3*1000 -> 11470000 | I3: =Yr!I3*1000 -> 3300000 | J3: =Yr!J3*1000 -> 1700000 | ... L3: =Yr!L3*1000 -> 120000 | M3: =Yr!N3*1000 -> 0 | N3: 0
A4: 3 | B4: Shaanxi | C4: =Yr!C4*1000 -> 600000 | D4: =Yr!D4*1000 -> 4400000 | E4: =Yr!E4*1000 -> 1000000 | F4: =Yr!F4*1000 -> 2300000 | G4: =Yr!G4*1000 -> 10460000 | H4: =Yr!H4*1000 -> 0 | I4: =Yr!I4*1000 -> 0 | J4: =Yr!J4*1000 -> 0 | ... N4: =Yr!N4*1000 -> 0
A5: 4 | B5: Anhui | C5: =Yr!C5*1000 -> 160000 | D5: =Yr!D5*1000 -> 150000 | E5: =Yr!E5*1000 -> 2000000 | F5: =Yr!F5*1000 -> 100000 | G5: =Yr!G5*1000 -> 900000 | H5: =Yr!H5*1000 -> 1800000 | I5: =Yr!I5*1000 -> 500000 | J5: =Yr!J5*1000 -> 0 | ... N5: =Yr!N5*1000 -> 0
A6: 5 | B6: Xinjiang | C6: =Yr!C6*1000 -> 400000 | D6: =Yr!D6*1000 -> 1200000 | E6: =Yr!E6*1000 -> 200000 | F6: =Yr!F6*1000 -> 85000 | G6: =Yr!G6*1000 -> 480000 | H6: =Yr!H6*1000 -> 150000 | I6: =Yr!I6*1000 -> 600000 | J6: =Yr!J6*1000 -> 2100000 | ... N6: =Yr!N6*1000 -> 0
A7: 6 | B7: Guangxi | C7: =Yr!C7*1000 -> 1800000 | D7: =Yr!D7*1000 -> 0 | E7: =Yr!E7*1000 -> 0 | F7: =Yr!F7*1000 -> 0 | G7: =Yr!G7*1000 -> 0 | H7: =Yr!H7*1000 -> 0 | I7: =Yr!I7*1000 -> 0 | J7: =Yr!J7*1000 -> 0 | ... N7: =Yr!N7*1000 -> 0
A8: 7 | B8: Shandong | C8: =Yr!C8*1000 -> 1900000 | D8: =Yr!D8*1000 -> 150000 | E8: =Yr!E8*1000 -> 600000 | F8: =Yr!F8*1000 -> 1270000 | G8: =Yr!G8*1000 -> 950000 | H8: =Yr!H8*1000 -> 200000 | I8: =Yr!I8*1000 -> 200000 | J8: =Yr!J8*1000 -> 400000 | ... N8: =Yr!N8*1000 -> 100000
A9: 8 | B9: Qinghai | C9: =Yr!C9*1000 -> 1400000 | D9: =Yr!D9*1000 -> 800000 | E9: =Yr!E9*1000 -> 1020000 | F9: =Yr!F9*1000 -> 0 | G9: =Yr!G9*1000 -> 0 | H9: =Yr!H9*1000 -> 0 | I9: =Yr!I9*1000 -> 0 | J9: =Yr!J9*1000 -> 0 | ... N9: =Yr!N9*1000 -> 0
A10: 9 | B10: Hainan | C10: =Yr!C10*1000 -> 1400000 | D10: =Yr!D10*1000 -> 0 | E10: =Yr!E10*1000 -> 0 | F10: =Yr!F10*1000 -> 0 | G10: =Yr!G10*1000 -> 0 | H10: =Yr!H10*1000 -> 0 | I10: =Yr!I10*1000 -> 0 | J10: =Yr!J10*1000 -> 0 | ... N10: =Yr!N10*1000 -> 0
A11: 10 | B11: Shanghai | C11: =Yr!C11*1000 -> 1000000 | D11: =Yr!D11*1000 -> 0 | E11: =Yr!E11*1000 -> 0 | F11: =Yr!F11*1000 -> 0 | G11: =Yr!G11*1000 -> 0 | H11: =Yr!H11*1000 -> 0 | I11: =Yr!I11*1000 -> 0 | J11: =Yr!J11*1000 -> 0 | ... N11: =Yr!N11*1000 -> 0
A12: 11 | B12: Shanxi | C12: =Yr!C12*1000 -> 600000 | D12: =Yr!D12*1000 -> 300000 | E12: =Yr!E12*1000 -> 1250000 | F12: =Yr!F12*1000 -> 1800000 | G12: =Yr!G12*1000 -> 1100000 | H12: =Yr!H12*1000 -> 900000 | I12: =Yr!I12*1000 -> 600000 | J12: =Yr!J12*1000 -> 700000 | ... N12: =Yr!N12*1000 -> 0
A13: 12 | B13: Chongqing | C13: =Yr!C13*1000 -> 2470000 | D13: =Yr!D13*1000 -> 0 | E13: =Yr!E13*1000 -> 0 | F13: =Yr!F13*1000 -> 0 | G13: =Yr!G13*1000 -> 0 | H13: =Yr!H13*1000 -> 0 | I13: =Yr!I13*1000 -> 0 | J13: =Yr!J13*1000 -> 0 | ... N13: =Yr!N13*1000 -> 0
A14: 13 | B14: Heilongjiang | C14: =Yr!C14*1000 -> 200000 | D14: =Yr!D14*1000 -> 390000 | E14: =Yr!E14*1000 -> 980000 | F14: =Yr!F14*1000 -> 30000 | G14: =Yr!G14*1000 -> 165000 | H14: =Yr!H14*1000 -> 0 | I14: =Yr!I14*1000 -> 0 | J14: =Yr!J14*1000 -> 0 | ... N14: =Yr!N14*1000 -> 0
A15: 14 | B15: Henan | C15: =Yr!C15*1000 -> 310000 | D15: =Yr!D15*1000 -> 800000 | E15: =Yr!E15*1000 -> 100000 | F15: =Yr!F15*1000 -> 1200000 | G15: =Yr!G15*1000 -> 540000 | H15: =Yr!H15*1000 -> 1500000 | I15: =Yr!I15*1000 -> 200000 | J15: =Yr!J15*1000 -> 0 | ... N15: =Yr!N15*1000 -> 0
... A27: 26 | B27: Jilin | C27: =Yr!C27*1000 -> 120000 | D27: =Yr!D27*1000 -> 0 | E27: =Yr!E27*1000 -> 0 | F27: =Yr!F27*1000 -> 0 | G27: =Yr!G27*1000 -> 0 | H27: =Yr!H27*1000 -> 0 | I27: =Yr!I27*1000 -> 0 | J27: =Yr!J27*1000 -> 0 | ... N27: =Yr!N27*1000 -> 0

Sheet Yr
C1: 1 | D1: 2 | E1: 3 | F1: 4 | G1: 5 | H1: 6 | I1: 7 | J1: 8 | K1: 9 | L1: 10 | M1: 11 | N1: 12
A2: 1 | B2: Ningxia | C2: 11740 | D2: 150 | E2: 0 | F2: 0 | G2: 0 | H2: 0 | I2: 0 | J2: 0 | K2: 0 | L2: 0 | M2: 0 | N2: 0
A3: 2 | B3: Inner Mongolia | C3: 700 | D3: 300 | E3: 2100 | F3: 150 | G3: 1680 | H3: 11470 | I3: 3300 | J3: 1700 | K3: 1170 | L3: 120 | N3: 0
A4: 3 | B4: Shaanxi | C4: 600 | D4: 4400 | E4: 1000 | F4: 2300 | G4: 10460 | H4: 0 | I4: 0 | J4: 0 | K4: 0 | L4: 0 | M4: 0 | N4: 0
A5: 4 | B5: Anhui | C5: 160 | D5: 150 | E5: 2000 | F5: 100 | G5: 900 | H5: 1800 | I5: 500 | J5: 0 | K5: 0 | L5: 0 | M5: 0 | N5: 0
A6: 5 | B6: Xinjiang | C6: 400 | D6: 1200 | E6: 200 | F6: 85 | G6: 480 | H6: 150 | I6: 600 | J6: 2100 | K6: 500 | L6: 0 | M6: 0 | N6: 0
A7: 6 | B7: Guangxi | C7: 1800 | D7: 0 | E7: 0 | F7: 0 | G7: 0 | H7: 0 | I7: 0 | J7: 0 | K7: 0 | L7: 0 | M7: 0 | N7: 0
A8: 7 | B8: Shandong | C8: 1900 | D8: 150 | E8: 600 | F8: 1270 | G8: 950 | H8: 200 | I8: 200 | J8: 400 | K8: 750 | L8: 600 | M8: 1470 | N8: 100
A9: 8 | B9: Qinghai | C9: 1400 | D9: 800 | E9: 1020 | F9: 0 | G9: 0 | H9: 0 | I9: 0 | J9: 0 | K9: 0 | L9: 0 | M9: 0 | N9: 0
A10: 9 | B10: Hainan | C10: 1400 | D10: 0 | E10: 0 | F10: 0 | G10: 0 | H10: 0 | I10: 0 | J10: 0 | K10: 0 | L10: 0 | M10: 0 | N10: 0
A11: 10 | B11: Shanghai | C11: 1000 | D11: 0 | E11: 0 | F11: 0 | G11: 0 | H11: 0 | I11: 0 | J11: 0 | K11: 0 | L11: 0 | M11: 0 | N11: 0
A12: 11 | B12: Shanxi | C12: 600 | D12: 300 | E12: 1250 | F12: 1800 | G12: 1100 | H12: 900 | I12: 600 | J12: 700 | K12: 500 | L12: 0 | M12: 0 | N12: 0
A13: 12 | B13: Chongqing | C13: 2470 | D13: 0 | E13: 0 | F13: 0 | G13: 0 | H13: 0 | I13: 0 | J13: 0 | K13: 0 | L13: 0 | M13: 0 | N13: 0
A14: 13 | B14: Heilongjiang | C14: 200 | D14: 390 | E14: 980 | F14: 30 | G14: 165 | H14: 0 | I14: 0 | J14: 0 | K14: 0 | L14: 0 | M14: 0 | N14: 0
A15: 14 | B15: Henan | C15: 310 | D15: 800 | E15: 100 | F15: 1200 | G15: 540 | H15: 1500 | I15: 200 | J15: 0 | K15: 0 | L15: 0 | M15: 0 | N15: 0
... A27: 26 | B27: Jilin | C27: 120 | D27: 0 | E27: 0 | F27: 0 | G27: 0 | H27: 0 | I27: 0 | J27: 0 | K27: 0 | L27: 0 | M27: 0 | N27: 0

Sheet Sheet2
A1: 省份 | B1: Province | C1: 产能（千吨/年） | D1: Location | E1: Capacity | F1: Percentage
A2: 陕西省 | B2: Shaanxi | C2: 16860 | D2: Northwest | E2: =SUM(C2:C6) -> 38585 | F2: =E2/$E$10 -> 0.35710319 | H2: 煤制甲醇 | I2: Coal based | J2: 81760
A3: 宁夏回族自治区 | B3: Ningxia | C3: 11890 | D3: North | E3: =SUM(C7:C10) -> 33010 | F3: =E3/$E$10 -> 0.30550671 | H3: 焦炉煤气甲醇 | I3: Coke based | J3: 15245
A4: 新疆维吾尔自治区 | B4: Xinjiang | C4: 5715 | D4: East | E4: =SUM(C11:C16) -> 18240 | F4: =E4/$E$10 -> 0.16881074 | H4: 天然气甲醇 | I4: Natural gas based | J4: 10670
A5: 青海省 | B5: Qinghai | C5: 3220 | D5: Southwest | E5: =SUM(C17:C20) -> 6630 | F5: =E5/$E$10 -> 0.061360481 | H5: 尾气制甲醇 | I5: Tailed gas based | J5: 375
A6: 甘肃省 | B6: Gansu | C6: 900 | D6: Centre | E6: =C21+C22 -> 5700 | F6: =E6/$E$10 -> 0.052753355
A7: 内蒙古自治区 | B7: Inner Mongolia | C7: 22690 | D7: South | E7: =C23+C24 -> 3200 | F7: =E7/$E$10 -> 0.029615919
A8: 山西省 | B8: Shanxi | C8: 7750 | D8: Northeast | E8: =C25+C26+C27 -> 2685 | F8: =E8/$E$10 -> 0.024849607
A9: 河北省 | B9: Hebei | C9: 2070
A10: 天津市 | B10: Tianjin | C10: 500 | E10: =SUM(E2:E8) -> 108050
A11: 山东省 | B11: Shandong | C11: 8590
A12: 安徽省 | B12: Anhui | C12: 5610
A13: 江苏省 | B13: Jiangsu | C13: 1780
A14: 上海市 | B14: Shanghai | C14: 1000
A15: 浙江省 | B15: Zhejiang | C15: 660
A16: 江西省 | B16: Jiangxi | C16: 600
A17: 重庆市 | B17: Chongqing | C17: 2470
A18: 四川省 | B18: Sichuan | C18: 1500
A19: 云南省 | B19: Yunnan | C19: 1360
A20: 贵州省 | B20: Guizhou | C20: 1300
A21: 河南省 | B21: Henan | C21: 4650
A22: 湖北省 | B22: Hubei | C22: 1050
... A27: 吉林省 | B27: Jilin | C27: 120
B39: Province | C39: Production capacity (kilo tonne/year) | D39: Province | E39: Production capacity (kilo tonne/year)
B40: Shaanxi | C40: 16860 | D40: Zhejiang | E40: 660
B41: Ningxia | C41: 11890 | D41: Jiangxi | E41: 600
B42: Xinjiang | C42: 5715 | D42: Chongqing | E42: 2470
B43: Qinghai | C43: 3220 | D43: Sichuan | E43: 1500
B44: Gansu | C44: 900 | D44: Yunnan | E44: 1360
B45: Inner Mongolia | C45: 22690 | D45: Guizhou | E45: 1300
B46: Shanxi | C46: 7750 | D46: Henan | E46: 4650
B47: Hebei | C47: 2070 | D47: Hubei | E47: 1050
B48: Tianjin | C48: 500 | D48: Guangxi | E48: 1800
B49: Shandong | C49: 8590 | D49: Hainan | E49: 1400
B50: Anhui | C50: 5610 | D50: Heilongjiang | E50: 1765
B51: Jiangsu | C51: 1780 | D51: Liaoning | E51: 800
B52: Shanghai | C52: 1000 | D52: Jilin | E52: 120

Sheet Sheet3
B1: LCOM | C1: Ref | D1: Energy usage | E1: Ref | F1: coal usage | H1: Carbon Emission | I1: Ref
A2: Coal | B2: 327.04, 334.20, 394.63 | C2: Arnaiz Del Pozo / Zhao | D2: 11.62 (MWh/ton) | E2: Zhao. | F2: 1.26 | H2: 2.2-4.3 | I2: Zhao
A3: Coke | B3: 174-323 | C3: YI /Portha | D3: 7.806 (MWh/ton) | E3: Ebrahimzadeh Sarvestani / Nguyen | H3: 1.95-2.20 (t/Coet) | I3: Yi | J3: 0.74
A4: Natural gas | B4: 198-295 | C4: Blumberg/ Arnaiz Del Pozo | D4: 8.05-10.28 (MWh/ton) | E4: ecoinvent | H4: 2.193 | I4: Methanol Institute
B6: Coke needs to be consdiered depending on the COG source (Yi
